<?xml version="1.0" encoding="utf-8"?>
<!-- This URDF was automatically created by SolidWorks to URDF Exporter! Originally created by Stephen Brawner (brawner@gmail.com) 
     Commit Version: 1.6.0-1-g15f4949  Build Version: 1.6.7594.29634
     For more information, please see http://wiki.ros.org/sw_urdf_exporter -->
<robot
  name="SVANM2_URDF">
  <link name="base">
    <visual>
      <origin rpy="0 0 0" xyz="0 0 0"/>
      <geometry>
        <box size="0.001 0.001 0.001"/>
      </geometry>
    </visual>
  </link> 
  <joint name="floating_base" type="fixed">
    <origin rpy="0 0 0" xyz="0 0 0"/>
    <parent link="base"/>
    <child link="trunk"/>
  </joint>  
  <link
    name="trunk">
    <inertial>
      <origin
        xyz="0.0046 -0.0009 0.0002"
        rpy="0 0 0" />
      <mass
        value="3.4234" />
      <inertia ixx="0.0163964" ixy="-0.0000159" ixz="0.0010427" iyy="0.0425922" iyz="-0.0000006" izz="0.0511340" />

    </inertial>
    <visual>
      <origin
        xyz="0 0 0"
        rpy="0 0 0" />
      <geometry>
        <mesh
          filename="../meshes/BASE.STL" />
      </geometry>
      <material
        name="">
        <color
          rgba="0.75294 0.75294 0.75294 1" />
      </material>
    </visual>
    <collision>
      <origin
        xyz="0 0 0"
        rpy="0 0 0" />
      <geometry>
        <mesh
          filename="../meshes/BASE.STL" />
      </geometry>
    </collision>
  </link>
  <link
    name="FR_hip">
    <inertial>
      <origin xyz="0.0492121 -0.0779589 0.0008006" rpy="0 0 0" />
      <mass value="1.3509490" />
      <inertia ixx="0.0033376" ixy="-0.0001656" ixz="0.0000090" iyy="0.0011263" iyz="-0.0000051" izz="0.0033905" />
   </inertial>
    <visual>
      <origin
        xyz="0 0 0"
        rpy="0 0 0" />
      <geometry>
        <mesh
          filename="../meshes/RF_HIP.STL" />
      </geometry>
      <material
        name="">
        <color
          rgba="0.75294 0.75294 0.75294 1" />
      </material>
    </visual>
    <collision>
      <origin
        xyz="0 0 0"
        rpy="0 0 0" />
      <geometry>
        <mesh
          filename="../meshes/RF_HIP.STL" />
      </geometry>
    </collision>
  </link>
  <joint
    name="FR_hip_joint"
    type="revolute">
    <origin
      xyz="0.155 -0.06 0"
      rpy="0 0 0" />
    <parent
      link="trunk" />
    <child
      link="FR_hip" />
    <axis
      xyz="1 0 0" />
    <limit
      lower="-0.8"
      upper="0.8"
      effort="20"
      velocity="52.4" />
  </joint>
  <link
    name="FR_thigh">
    <inertial>
      <origin xyz="-0.0000042 0.0008381 -0.0603416" rpy="0 0 0" />
      <mass value="0.2502465" />
      <inertia ixx="0.0011437" ixy="0.0000000" ixz="-0.0000001" iyy="0.0011591" iyz="0.0000243" izz="0.0000720" />
    </inertial>
    <visual>
      <origin
        xyz="0 0 0"
        rpy="0 0 0" />
      <geometry>
        <mesh
          filename="../meshes/RF_THIGH.STL" />
      </geometry>
      <material
        name="">
        <color
          rgba="0.75294 0.75294 0.75294 1" />
      </material>
    </visual>
    <collision>
      <origin
        xyz="0 0 0"
        rpy="0 0 0" />
      <geometry>
        <mesh
          filename="../meshes/RF_THIGH.STL" />
      </geometry>
    </collision>
  </link>
  <joint
    name="FR_thigh_joint"
    type="revolute">
    <origin
      xyz="0.043751 -0.0796 0"
      rpy="0 0 0" />
    <parent
      link="FR_hip" />
    <child
      link="FR_thigh" />
    <axis
      xyz="0 1 0" />
    <limit effort="55" lower="-1.0471975512" upper="4.18879020479" velocity="28.6"/>

  </joint>
  <link
    name="FR_calf">
    <inertial>
      <origin xyz="-0.0035383 -0.0000273 -0.0688420" rpy="0 0 0" />
      <mass value="0.2017400" />
      <inertia ixx="0.0010436" ixy="-0.0000001" ixz="-0.0000693" iyy="0.0010692" iyz="-0.0000010" izz="0.0000424" />
    </inertial>
    <visual>
      <origin
        xyz="0 0 0"
        rpy="0 0 0" />
      <geometry>
        <mesh
          filename="../meshes/RF_SHANK.STL" />
      </geometry>
      <material
        name="">
        <color
          rgba="0.75294 0.75294 0.75294 1" />
      </material>
    </visual>
    <collision>
      <origin
        xyz="0 0 0"
        rpy="0 0 0" />
      <geometry>
        <mesh
          filename="../meshes/RF_SHANK.STL" />
      </geometry>
    </collision>
  </link>
  <joint
    name="FR_calf_joint"
    type="revolute">
    <origin
      xyz="0 0 -0.1915"
      rpy="0 0 0" />
    <parent
      link="FR_thigh" />
    <child
      link="FR_calf" />
    <axis
      xyz="0 1 0" />
    <limit effort="55" lower="-2.69653369433" upper="-0.916297857297" velocity="28.6"/>
  </joint>
  <joint name="FR_foot_fixed" type="fixed" dont_collapse="true">
    <origin
      xyz="-0.0 0 -0.16693"
      rpy="0 0 0" />
    <parent
      link="FR_calf" />
    <child
      link="FR_foot" />
  </joint>
  <link
    name="FL_hip">
    <inertial>
      <origin xyz="0.0492121 0.0779589 0.0008006" rpy="0 0 0" />
      <mass value="1.3509490" />
      <inertia ixx="0.0033376" ixy="0.0001656" ixz="0.0000090" iyy="0.0011263" iyz="0.0000051" izz="0.0033905" />
    </inertial>
    <visual>
      <origin
        xyz="0 0 0"
        rpy="0 0 0" />
      <geometry>
        <mesh
          filename="../meshes/LF_HIP.STL" />
      </geometry>
      <material
        name="">
        <color
          rgba="0.752941176470588 0.752941176470588 0.752941176470588 1" />
      </material>
    </visual>
    <collision>
      <origin
        xyz="0 0 0"
        rpy="0 0 0" />
      <geometry>
        <mesh
          filename="../meshes/LF_HIP.STL" />
      </geometry>
    </collision>
  </link>
  <joint
    name="FL_hip_joint"
    type="revolute">
    <origin
      xyz="0.155 0.06 0"
      rpy="0 0 0" />
    <parent
      link="trunk" />
    <child
      link="FL_hip" />
    <axis
      xyz="1 0 0" />
    <limit effort="20" lower="-0.802851455917" upper="0.802851455917" velocity="52.4"/>

  </joint>
  <link
    name="FL_thigh">
    <inertial>
      <origin xyz="-0.0000042 -0.0008381 -0.0603416" rpy="0 0 0" />
      <mass value="0.2502465" />
      <inertia ixx="0.0011437" ixy="0.0000000" ixz="0.0000001" iyy="0.0011591" iyz="0.0000243" izz="0.0000720" />
    </inertial>
    <visual>
      <origin
        xyz="0 0 0"
        rpy="0 0 0" />
      <geometry>
        <mesh
          filename="../meshes/LF_THIGH.STL" />
      </geometry>
      <material
        name="">
        <color
          rgba="0.752941176470588 0.752941176470588 0.752941176470588 1" />
      </material>
    </visual>
    <collision>
      <origin
        xyz="0 0 0"
        rpy="0 0 0" />
      <geometry>
        <mesh
          filename="../meshes/LF_THIGH.STL" />
      </geometry>
    </collision>
  </link>
  <joint
    name="FL_thigh_joint"
    type="revolute">
    <origin
      xyz="0.043751 0.0796 0"
      rpy="0 0 0" />
    <parent
      link="FL_hip" />
    <child
      link="FL_thigh" />
    <axis
      xyz="0 1 0" />
    <limit effort="55" lower="-1.0471975512" upper="4.18879020479" velocity="28.6"/>

  </joint>
  <link
    name="FL_calf">
    <inertial>
      <origin xyz="-0.0035383 0.0000273 -0.0688420" rpy="0 0 0" />
      <mass value="0.2017400" />
      <inertia ixx="0.0010436" ixy="0.0000001" ixz="-0.0000693" iyy="0.0010692" iyz="0.0000010" izz="0.0000424" />
    </inertial>
    <visual>
      <origin
        xyz="0 0 0"
        rpy="0 0 0" />
      <geometry>
        <mesh
          filename="../meshes/LF_SHANK.STL" />
      </geometry>
      <material
        name="">
        <color
          rgba="0.752941176470588 0.752941176470588 0.752941176470588 1" />
      </material>
    </visual>
    <collision>
      <origin
        xyz="0 0 0"
        rpy="0 0 0" />
      <geometry>
        <mesh
          filename="../meshes/LF_SHANK.STL" />
      </geometry>
    </collision>
  </link>
  <joint
    name="FL_calf_joint"
    type="revolute">
    <origin
      xyz="0 0 -0.1915"
      rpy="0 0 0" />
    <parent
      link="FL_thigh" />
    <child
      link="FL_calf" />
    <axis
      xyz="0 1 0" />
    <limit effort="55" lower="-2.69653369433" upper="-0.916297857297" velocity="28.6"/>

  </joint>
  <joint name="FL_foot_fixed" type="fixed" dont_collapse="true">
    <origin
      xyz="-0.0 0 -0.16693"
      rpy="0 0 0" />
    <parent
      link="FL_calf" />
    <child
      link="FL_foot" />
  </joint>

  <link
    name="RR_hip">
    <inertial>
      <origin xyz="-0.0492121 -0.0779589 0.0008006" rpy="0 0 0" />
      <mass value="1.3509490" />
      <inertia ixx="0.0033376" ixy="0.0001656" ixz="-0.0000090" iyy="0.0011263" iyz="-0.0000051" izz="0.0033905" />
    </inertial>
    <visual>
      <origin
        xyz="0 0 0"
        rpy="0 0 0" />
      <geometry>
        <mesh
          filename="../meshes/RH_HIP.STL" />
      </geometry>
      <material
        name="">
        <color
          rgba="1 1 1 1" />
      </material>
    </visual>
    <collision>
      <origin
        xyz="0 0 0"
        rpy="0 0 0" />
      <geometry>
        <mesh
          filename="../meshes/RH_HIP.STL" />
      </geometry>
    </collision>
  </link>
  <joint
    name="RR_hip_joint"
    type="revolute">
    <origin
      xyz="-0.155 -0.06 0"
      rpy="0 0 0" />
    <parent
      link="trunk" />
    <child
      link="RR_hip" />
    <axis
      xyz="1 0 0" />
    <limit effort="20" lower="-0.802851455917" upper="0.802851455917" velocity="52.4"/>

  </joint>
  <link
    name="RR_thigh">
    <inertial>
      <origin xyz="0.0000042 0.0008381 -0.0603416" rpy="0 0 0" />
      <mass value="0.2502465" />
      <inertia ixx="0.0011437" ixy="0.0000000" ixz="-0.0000001" iyy="0.0011591" iyz="-0.0000243" izz="0.0000720" />
    </inertial>
    <visual>
      <origin
        xyz="0 0 0"
        rpy="0 0 0" />
      <geometry>
        <mesh
          filename="../meshes/RH_THIGH.STL" />
      </geometry>
      <material
        name="">
        <color
          rgba="0.752941176470588 0.752941176470588 0.752941176470588 1" />
      </material>
    </visual>
    <collision>
      <origin
        xyz="0 0 0"
        rpy="0 0 0" />
      <geometry>
        <mesh
          filename="../meshes/RH_THIGH.STL" />
      </geometry>
    </collision>
  </link>
  <joint
    name="RR_thigh_joint"
    type="revolute">
    <origin
      xyz="-0.043751 -0.0796 0"
      rpy="0 0 0" />
    <parent
      link="RR_hip" />
    <child
      link="RR_thigh" />
    <axis
      xyz="0 1 0" />
    <limit effort="55" lower="-1.0471975512" upper="4.18879020479" velocity="28.6"/>

  </joint>
  <link
    name="RR_calf">
    <inertial>
      <origin xyz="0.0035383 0.0000273 -0.0688420" rpy="0 0 0" />
      <mass value="0.2017400" />
      <inertia ixx="0.0010436" ixy="0.0000001" ixz="-0.0000693" iyy="0.0010692" iyz="-0.0000010" izz="0.0000424" />
    </inertial>
    <visual>
      <origin
        xyz="0 0 0"
        rpy="0 0 0" />
      <geometry>
        <mesh
          filename="../meshes/RH_SHANK.STL" />
      </geometry>
      <material
        name="">
        <color
          rgba="0.752941176470588 0.752941176470588 0.752941176470588 1" />
      </material>
    </visual>
    <collision>
      <origin
        xyz="0 0 0"
        rpy="0 0 0" />
      <geometry>
        <mesh
          filename="../meshes/RH_SHANK.STL" />
      </geometry>
    </collision>
  </link>
  <joint
    name="RR_calf_joint"
    type="revolute">
    <origin
      xyz="0 0 -0.1915"
      rpy="0 0 0" />
    <parent
      link="RR_thigh" />
    <child
      link="RR_calf" />
    <axis
      xyz="0 1 0" />
    <limit effort="55" lower="-2.69653369433" upper="-0.916297857297" velocity="28.6"/>

  </joint>
    <joint name="RR_foot_fixed" type="fixed" dont_collapse="true">
    <origin
      xyz="-0.0 0 -0.16802"
      rpy="0 0 0" />
    <parent
      link="RR_calf" />
    <child
      link="RR_foot" />
  </joint>
  <link
    name="RL_hip">
    <inertial>
      <origin xyz="-0.0492121 0.0779589 0.0008006" rpy="0 0 0" />
      <mass value="1.3509490" />
      <inertia ixx="0.0033376" ixy="-0.0001656" ixz="-0.0000090" iyy="0.0011263" iyz="0.0000051" izz="0.0033905" />
    </inertial>
    <visual>
      <origin
        xyz="0 0 0"
        rpy="0 0 0" />
      <geometry>
        <mesh
          filename="../meshes/LH_HIP.STL" />
      </geometry>
      <material
        name="">
        <color
          rgba="0.752941176470588 0.752941176470588 0.752941176470588 1" />
      </material>
    </visual>
    <collision>
      <origin
        xyz="0 0 0"
        rpy="0 0 0" />
      <geometry>
        <mesh
          filename="../meshes/LH_HIP.STL" />
      </geometry>
    </collision>
  </link>
  <joint
    name="RL_hip_joint"
    type="revolute">
    <origin
      xyz="-0.155 0.06 0"
      rpy="0 0 0" />
    <parent
      link="trunk" />
    <child
      link="RL_hip" />
    <axis
      xyz="1 0 0" />
    <limit effort="20" lower="-0.802851455917" upper="0.802851455917" velocity="52.4"/>

  </joint>
  <link
    name="RL_thigh">
    <inertial>
      <origin xyz="-0.0000042 -0.0008381 -0.0603416" rpy="0 0 0" />
      <mass value="0.2502465" />
      <inertia ixx="0.0011437" ixy="0.0000000" ixz="-0.0000001" iyy="0.0011591" iyz="0.0000243" izz="0.0000720" />
    </inertial>
    <visual>
      <origin
        xyz="0 0 0"
        rpy="0 0 0" />
      <geometry>
        <mesh
          filename="../meshes/LH_THIGH.STL" />
      </geometry>
      <material
        name="">
        <color
          rgba="0.752941176470588 0.752941176470588 0.752941176470588 1" />
      </material>
    </visual>
    <collision>
      <origin
        xyz="0 0 0"
        rpy="0 0 0" />
      <geometry>
        <mesh
          filename="../meshes/LH_THIGH.STL" />
      </geometry>
    </collision>
  </link>
  <joint
    name="RL_thigh_joint"
    type="revolute">
    <origin
      xyz="-0.043751 0.0796 0"
      rpy="0 0 0" />
    <parent
      link="RL_hip" />
    <child
      link="RL_thigh" />
    <axis
      xyz="0 1 0" />
    <limit effort="55" lower="-1.0471975512" upper="4.18879020479" velocity="28.6"/>

  </joint>
  <link
    name="RL_calf">
    <inertial>
      <origin xyz="0.0035383 -0.0000273 -0.0688420" rpy="0 0 0" />
      <mass value="0.2017400" />
      <inertia ixx="0.0010436" ixy="-0.0000001" ixz="-0.0000693" iyy="0.0010692" iyz="0.0000010" izz="0.0000424" />
    </inertial>
    <visual>
      <origin
        xyz="0 0 0"
        rpy="0 0 0" />
      <geometry>
        <mesh
          filename="../meshes/LH_SHANK.STL" />
      </geometry>
      <material
        name="">
        <color
          rgba="0.752941176470588 0.752941176470588 0.752941176470588 1" />
      </material>
    </visual>
    <collision>
      <origin
        xyz="0 0 0"
        rpy="0 0 0" />
      <geometry>
        <mesh
          filename="../meshes/LH_SHANK.STL" />
      </geometry>
    </collision>
  </link>
  <joint
    name="RL_calf_joint"
    type="revolute">
    <origin
      xyz="0 0 -0.1915"
      rpy="0 0 0" />
    <parent
      link="RL_thigh" />
    <child
      link="RL_calf" />
    <axis
      xyz="0 1 0" />
    <limit effort="55" lower="-2.69653369433" upper="-0.916297857297" velocity="28.6"/>

  </joint>

  <link name="FR_foot">
    <inertial>
        <origin xyz="0.0014979844072685 1.99840144432528E-15 7.77349055681165E-05"
        rpy="0 0 0" /> 
        <mass value="0.025" />
        <inertia ixx="2e-6" ixy="0" ixz="0" iyy="2e-6" iyz="0" izz="2e-6" />
      </inertial>
      <visual>
        <origin xyz="0 0 0" rpy="0 0 0" />
        <geometry>
          <sphere radius="0.02" />
        </geometry>
      </visual>
      <collision>
        <origin xyz="0 0 0" rpy="0 0 0" />
        <geometry>
          <sphere radius="0.02" />
        </geometry>
      </collision>
  </link>
  <link name="FL_foot">
    <inertial>
        <origin xyz="0.0014979844072685 1.99840144432528E-15 7.77349055681165E-05"
        rpy="0 0 0" /> 
        <mass value="0.025" />
        <inertia ixx="2e-6" ixy="0" ixz="0" iyy="2e-6" iyz="0" izz="2e-6" />
      </inertial>
      <visual>
        <origin xyz="0 0 0" rpy="0 0 0" />
        <geometry>
          <sphere radius="0.02" />
        </geometry>
      </visual>
      <collision>
        <origin xyz="0 0 0" rpy="0 0 0" />
        <geometry>
          <sphere radius="0.02" />
        </geometry>
      </collision>
  </link>
  <link name="RL_foot">
    <inertial>
        <origin xyz="0.0014979844072685 1.99840144432528E-15 7.77349055681165E-05"
        rpy="0 0 0" /> 
        <mass value="0.025" />
        <inertia ixx="2e-6" ixy="0" ixz="0" iyy="2e-6" iyz="0" izz="2e-6" />
      </inertial>
      <visual>
        <origin xyz="0 0 0" rpy="0 0 0" />
        <geometry>
          <sphere radius="0.02" />
        </geometry>
      </visual>
      <collision>
        <origin xyz="0 0 0" rpy="0 0 0" />
        <geometry>
          <sphere radius="0.02" />
        </geometry>
      </collision>
  </link>
  <link name="RR_foot">
    <inertial>
        <origin xyz="0.0014979844072685 1.99840144432528E-15 7.77349055681165E-05"
        rpy="0 0 0" /> 
        <mass value="0.025" />
        <inertia ixx="2e-6" ixy="0" ixz="0" iyy="2e-6" iyz="0" izz="2e-6" />
      </inertial>
      <visual>
        <origin xyz="0 0 0" rpy="0 0 0" />
        <geometry>
          <sphere radius="0.02" />
        </geometry>
      </visual>
      <collision>
        <origin xyz="0 0 0" rpy="0 0 0" />
        <geometry>
          <sphere radius="0.02" />
        </geometry>
      </collision>
  </link>
  <joint name="RL_foot_fixed" type="fixed" dont_collapse="true" >
    <origin
      xyz="-0.0 0 -0.16802"
      rpy="0 0 0" />
    <parent
      link="RL_calf" />
    <child
      link="RL_foot" />
  </joint>
</robot>



