<?xml version="1.0" encoding="utf-8"?>
<!-- This URDF was automatically created by SolidWorks to URDF Exporter! Originally created by Stephen Brawner (brawner@gmail.com) 
     Commit Version: 1.6.0-1-g15f4949  Build Version: 1.6.7594.29634
     For more information, please see http://wiki.ros.org/sw_urdf_exporter -->
<robot
  name="SVANM2_URDF">
  <material name="black">
    <color rgba="0.1059 0.1059 0.1059 1.0"/>
  </material>
  <material name="blue">
    <color rgba="0.0 0.0 0.8 1.0"/>
  </material>
  <material name="green">
    <color rgba="0.345 0.4823 0.294 1.0"/>
  </material>
  <material name="grey_shank">
    <color rgba="0.2078 0.2078 0.2078 1.0"/>
  </material>
    <material name="grey_actuator">
    <color rgba="0.5196 0.5196 0.5196 1.0"/>
  </material>
  <material name="silver">
    <color rgba="0.913725490196 0.913725490196 0.847058823529 1.0"/>
  </material>
  <material name="orange">
    <!-- <color rgba="1.0 0.423529411765 0.0392156862745 1.0"/> -->
    <color rgba="0.12 0.15 0.2 1.0"/>
  </material>
  <material name="brown">
    <color rgba="0.870588235294 0.811764705882 0.764705882353 1.0"/>
  </material>
  <material name="red">
    <color rgba="0.8 0.0 0.0 1.0"/>
  </material>
  <material name="white">
    <color rgba="1.0 1.0 1.0 1.0"/>
  </material>
  <link name="base">
    <visual>
      <origin rpy="0 0 0" xyz="0 0 0"/>
      <geometry>
        <box size="0.001 0.001 0.001"/>
      </geometry>
    </visual>
  </link> 
  <joint name="floating_base" type="fixed">
    <origin rpy="0 0 0" xyz="0 0 0"/>
    <parent link="base"/>
    <child link="trunk"/>
  </joint>  
  <link
    name="trunk">
    <inertial>
      <origin xyz="0.0047249 -0.0000177 0.0011585" rpy="0 0 0" />
      <mass
        value="3.4234" />
      <inertia ixx="0.0163964" ixy="-0.0000159" ixz="0.0010427" iyy="0.0425922" iyz="-0.0000006" izz="0.0511340" />

    </inertial>
    <visual>
      <origin
        xyz="0 0 0"
        rpy="0 0 0" />
      <geometry>
        <mesh
          filename="../meshes/BASE.STL" />
      </geometry>
      <material
        name="green"/>
    </visual>
    <collision>
      <origin
        xyz="0 0 0"
        rpy="0 0 0" />
      <geometry>
        <mesh
          filename="../meshes_a1/BASE.dae" />
      </geometry>
    </collision>
  </link>
  <link
    name="FR_hip">
    <inertial>
      <origin xyz="0.0492121 -0.0779589 0.0008006" rpy="0 0 0" />
      <mass value="1.3509490" />
      <inertia ixx="0.0033376" ixy="-0.0001656" ixz="0.0000090" iyy="0.0011263" iyz="-0.0000051" izz="0.0033905" />
   </inertial>
    <visual>
      <origin
        xyz="0 0 0"
        rpy="0 0 0" />
      <geometry>
        <mesh
          filename="../meshes/RF_HIP.STL" />
      </geometry>
      <material
        name="grey_actuator"/>
    </visual>
    <collision>
      <origin
        xyz="0 0 0"
        rpy="0 0 0" />
      <geometry>
        <mesh
          filename="../meshes_a1/RF_HIP.dae" />
      </geometry>
    </collision>
  </link>
  <joint
    name="FR_hip_joint"
    type="revolute">
    <origin
      xyz="0.155 -0.06 0"
      rpy="0 0 0" />
    <parent
      link="trunk" />
    <child
      link="FR_hip" />
    <axis
      xyz="1 0 0" />
    <limit
      lower="-4.8"
      upper="4.8"
      effort="20"
      velocity="10.4" />
  </joint>
  <link
    name="FR_thigh">
    <inertial>
      <origin xyz="-0.0000042 0.0008381 -0.0603416" rpy="0 0 0" />
      <mass value="0.2502465" />
      <inertia ixx="0.0011437" ixy="0.0000000" ixz="-0.0000001" iyy="0.0011591" iyz="0.0000243" izz="0.0000720" />
    </inertial>
    <visual>
      <origin
        xyz="0 0 0"
        rpy="0 0 0" />
      <geometry>
        <mesh
          filename="../meshes/RF_THIGH.STL" />
      </geometry>
      <material
        name="grey_shank"/>
    </visual>
    <collision>
      <origin
        xyz="0 0 0"
        rpy="0 0 0" />
      <geometry>
        <mesh
          filename="../meshes_a1/RF_THIGH.dae" />
      </geometry>
    </collision>
  </link>
  <joint
    name="FR_thigh_joint"
    type="revolute">
    <origin
      xyz="0.043751 -0.0796 0"
      rpy="0 0 0" />
    <parent
      link="FR_hip" />
    <child
      link="FR_thigh" />
    <axis
      xyz="0 1 0" />
    <limit effort="55" lower="-4.0471975512" upper="4.18879020479" velocity="10.6"/>

  </joint>
  <link
    name="FR_calf">
    <inertial>
      <origin xyz="-0.0035383 -0.0000273 -0.0688420" rpy="0 0 0" />
      <mass value="0.2017400" />
      <inertia ixx="0.0010436" ixy="-0.0000001" ixz="-0.0000693" iyy="0.0010692" iyz="-0.0000010" izz="0.0000424" />
    </inertial>
    <visual>
      <origin
        xyz="0 0 0"
        rpy="0 0 0" />
      <geometry>
        <mesh
          filename="../meshes/RF_SHANK.STL" />
      </geometry>
      <material
        name="grey_shank"/>
    </visual>
    <collision>
      <origin
        xyz="0 0 0"
        rpy="0 0 0" />
      <geometry>
        <mesh
          filename="../meshes_a1/RF_SHANK.dae" />
      </geometry>
    </collision>
  </link>
  <joint
    name="FR_calf_joint"
    type="revolute">
    <origin
      xyz="0 0 -0.1915"
      rpy="0 0 0" />
    <parent
      link="FR_thigh" />
    <child
      link="FR_calf" />
    <axis
      xyz="0 1 0" />
    <limit effort="55" lower="-4.69653369433" upper="4.916297857297" velocity="10.6"/>
  </joint>
  <joint name="fr_dummy_j" type="fixed" dont_collapse="true">
    <origin
      xyz="-0.0 0 -0.16693"
      rpy="0 0 0" />
    <parent
      link="FR_calf" />
    <child
      link="FR_foot" />
  </joint>
  <link
    name="FL_hip">
    <inertial>
      <origin xyz="0.0492121 0.0779589 0.0008006" rpy="0 0 0" />
      <mass value="1.3509490" />
      <inertia ixx="0.0033376" ixy="0.0001656" ixz="0.0000090" iyy="0.0011263" iyz="0.0000051" izz="0.0033905" />
    </inertial>
    <visual>
      <origin
        xyz="0 0 0"
        rpy="0 0 0" />
      <geometry>
        <mesh
          filename="../meshes/LF_HIP.STL" />
      </geometry>
      <material
        name="grey_actuator"/>
    </visual>
    <collision>
      <origin
        xyz="0 0 0"
        rpy="0 0 0" />
      <geometry>
        <mesh
          filename="../meshes_a1/LF_HIP.dae" />
      </geometry>
    </collision>
  </link>
  <joint
    name="FL_hip_joint"
    type="revolute">
    <origin
      xyz="0.155 0.06 0"
      rpy="0 0 0" />
    <parent
      link="trunk" />
    <child
      link="FL_hip" />
    <axis
      xyz="1 0 0" />
    <limit effort="20" lower="-3.802851455917" upper="3.802851455917" velocity="10.4"/>

  </joint>
  <link
    name="FL_thigh">
    <inertial>
      <origin xyz="-0.0000042 -0.0008381 -0.0603416" rpy="0 0 0" />
      <mass value="0.2502465" />
      <inertia ixx="0.0011437" ixy="0.0000000" ixz="0.0000001" iyy="0.0011591" iyz="0.0000243" izz="0.0000720" />
    </inertial>
    <visual>
      <origin
        xyz="0 0 0"
        rpy="0 0 0" />
      <geometry>
        <mesh
          filename="../meshes/LF_THIGH.STL" />
      </geometry>
      <material
        name="grey_shank"/>
    </visual>
    <collision>
      <origin
        xyz="0 0 0"
        rpy="0 0 0" />
      <geometry>
        <mesh
          filename="../meshes_a1/LF_THIGH.dae" />
      </geometry>
    </collision>
  </link>
  <joint
    name="FL_thigh_joint"
    type="revolute">
    <origin
      xyz="0.043751 0.0796 0"
      rpy="0 0 0" />
    <parent
      link="FL_hip" />
    <child
      link="FL_thigh" />
    <axis
      xyz="0 1 0" />
    <limit effort="55" lower="-4.0471975512" upper="4.18879020479" velocity="10.6"/>

  </joint>
  <link
    name="FL_calf">
    <inertial>
      <origin xyz="-0.0035383 0.0000273 -0.0688420" rpy="0 0 0" />
      <mass value="0.2017400" />
      <inertia ixx="0.0010436" ixy="0.0000001" ixz="-0.0000693" iyy="0.0010692" iyz="0.0000010" izz="0.0000424" />
    </inertial>
    <visual>
      <origin
        xyz="0 0 0"
        rpy="0 0 0" />
      <geometry>
        <mesh
          filename="../meshes/LF_SHANK.STL" />
      </geometry>
      <material
        name="grey_shank"/>
    </visual>
    <collision>
      <origin
        xyz="0 0 0"
        rpy="0 0 0" />
      <geometry>
        <mesh
          filename="../meshes_a1/LF_SHANK.dae" />
      </geometry>
    </collision>
  </link>
  <joint
    name="FL_calf_joint"
    type="revolute">
    <origin
      xyz="0 0 -0.1915"
      rpy="0 0 0" />
    <parent
      link="FL_thigh" />
    <child
      link="FL_calf" />
    <axis
      xyz="0 1 0" />
    <limit effort="55" lower="-4.69653369433" upper="4.916297857297" velocity="10.6"/>

  </joint>
  <joint name="FL_foot_fixed" type="fixed" dont_collapse="true">
    <origin
      xyz="-0.0 0 -0.16693"
      rpy="0 0 0" />
    <parent
      link="FL_calf" />
    <child
      link="FL_foot" />
  </joint>

  <link
    name="RR_hip">
    <inertial>
      <origin xyz="-0.0492121 -0.0779589 0.0008006" rpy="0 0 0" />
      <mass value="1.3509490" />
      <inertia ixx="0.0033376" ixy="0.0001656" ixz="-0.0000090" iyy="0.0011263" iyz="-0.0000051" izz="0.0033905" />
    </inertial>
    <visual>
      <origin
        xyz="0 0 0"
        rpy="0 0 0" />
      <geometry>
        <mesh
          filename="../meshes/RH_HIP.STL" />
      </geometry>
      <material
        name="grey_actuator"/>
    </visual>
    <collision>
      <origin
        xyz="0 0 0"
        rpy="0 0 0" />
      <geometry>
        <mesh
          filename="../meshes_a1/RH_HIP.dae" />
      </geometry>
    </collision>
  </link>
  <joint
    name="RR_hip_joint"
    type="revolute">
    <origin
      xyz="-0.155 -0.06 0"
      rpy="0 0 0" />
    <parent
      link="trunk" />
    <child
      link="RR_hip" />
    <axis
      xyz="1 0 0" />
    <limit effort="20" lower="-4.802851455917" upper="4.802851455917" velocity="10.4"/>

  </joint>
  <link
    name="RR_thigh">
    <inertial>
      <origin xyz="0.0000042 0.0008381 -0.0603416" rpy="0 0 0" />
      <mass value="0.2502465" />
      <inertia ixx="0.0011437" ixy="0.0000000" ixz="-0.0000001" iyy="0.0011591" iyz="-0.0000243" izz="0.0000720" />
    </inertial>
    <visual>
      <origin
        xyz="0 0 0"
        rpy="0 0 0" />
      <geometry>
        <mesh
          filename="../meshes/RH_THIGH.STL" />
      </geometry>
      <material
        name="grey_shank"/>
    </visual>
    <collision>
      <origin
        xyz="0 0 0"
        rpy="0 0 0" />
      <geometry>
        <mesh
          filename="../meshes_a1/RH_THIGH.dae" />
      </geometry>
    </collision>
  </link>
  <joint
    name="RR_thigh_joint"
    type="revolute">
    <origin
      xyz="-0.043751 -0.0796 0"
      rpy="0 0 0" />
    <parent
      link="RR_hip" />
    <child
      link="RR_thigh" />
    <axis
      xyz="0 1 0" />
    <limit effort="55" lower="-4.0471975512" upper="4.18879020479" velocity="10.6"/>

  </joint>
  <link
    name="RR_calf">
    <inertial>
      <origin xyz="0.0035383 0.0000273 -0.0688420" rpy="0 0 0" />
      <mass value="0.2017400" />
      <inertia ixx="0.0010436" ixy="0.0000001" ixz="-0.0000693" iyy="0.0010692" iyz="-0.0000010" izz="0.0000424" />
    </inertial>
    <visual>
      <origin
        xyz="0 0 0"
        rpy="0 0 0" />
      <geometry>
        <mesh
          filename="../meshes/RH_SHANK.STL" />
      </geometry>
      <material
        name="grey_shank"/>
    </visual>
    <collision>
      <origin
        xyz="0 0 0"
        rpy="0 0 0" />
      <geometry>
        <mesh
          filename="../meshes_a1/RH_SHANK.dae" />
      </geometry>
    </collision>
  </link>
  <joint
    name="RR_calf_joint"
    type="revolute">
    <origin
      xyz="0 0 -0.1915"
      rpy="0 0 0" />
    <parent
      link="RR_thigh" />
    <child
      link="RR_calf" />
    <axis
      xyz="0 1 0" />
    <limit effort="55" lower="-4.69653369433" upper="4.916297857297" velocity="10.6"/>

  </joint>
    <joint name="RR_foot_fixed" type="fixed" dont_collapse="true">
    <origin
      xyz="-0.0 0 -0.16802"
      rpy="0 0 0" />
    <parent
      link="RR_calf" />
    <child
      link="RR_foot" />
  </joint>
  <link
    name="RL_hip">
    <inertial>
      <origin xyz="-0.0492121 0.0779589 0.0008006" rpy="0 0 0" />
      <mass value="1.3509490" />
      <inertia ixx="0.0033376" ixy="-0.0001656" ixz="-0.0000090" iyy="0.0011263" iyz="0.0000051" izz="0.0033905" />
    </inertial>
    <visual>
      <origin
        xyz="0 0 0"
        rpy="0 0 0" />
      <geometry>
        <mesh
          filename="../meshes/LH_HIP.STL" />
      </geometry>
      <material
        name="grey_actuator"/>
    </visual>
    <collision>
      <origin
        xyz="0 0 0"
        rpy="0 0 0" />
      <geometry>
        <mesh
          filename="../meshes_a1/LH_HIP.dae" />
      </geometry>
    </collision>
  </link>
  <joint
    name="RL_hip_joint"
    type="revolute">
    <origin
      xyz="-0.155 0.06 0"
      rpy="0 0 0" />
    <parent
      link="trunk" />
    <child
      link="RL_hip" />
    <axis
      xyz="1 0 0" />
    <limit effort="20" lower="-4.802851455917" upper="4.802851455917" velocity="10.4"/>

  </joint>
  <link
    name="RL_thigh">
    <inertial>
      <origin xyz="-0.0000042 -0.0008381 -0.0603416" rpy="0 0 0" />
      <mass value="0.2502465" />
      <inertia ixx="0.0011437" ixy="0.0000000" ixz="-0.0000001" iyy="0.0011591" iyz="0.0000243" izz="0.0000720" />
    </inertial>
    <visual>
      <origin
        xyz="0 0 0"
        rpy="0 0 0" />
      <geometry>
        <mesh
          filename="../meshes/LH_THIGH.STL" />
      </geometry>
      <material
        name="grey_shank"/>
    </visual>
    <collision>
      <origin
        xyz="0 0 0"
        rpy="0 0 0" />
      <geometry>
        <mesh
          filename="../meshes_a1/LH_THIGH.dae" />
      </geometry>
    </collision>
  </link>
  <joint
    name="RL_thigh_joint"
    type="revolute">
    <origin
      xyz="-0.043751 0.0796 0"
      rpy="0 0 0" />
    <parent
      link="RL_hip" />
    <child
      link="RL_thigh" />
    <axis
      xyz="0 1 0" />
    <limit effort="55" lower="-4.0471975512" upper="4.18879020479" velocity="10.6"/>

  </joint>
  <link
    name="RL_calf">
    <inertial>
      <origin xyz="0.0035383 -0.0000273 -0.0688420" rpy="0 0 0" />
      <mass value="0.2017400" />
      <inertia ixx="0.0010436" ixy="-0.0000001" ixz="-0.0000693" iyy="0.0010692" iyz="0.0000010" izz="0.0000424" />
    </inertial>
    <visual>
      <origin
        xyz="0 0 0"
        rpy="0 0 0" />
      <geometry>
        <mesh
          filename="../meshes/LH_SHANK.STL" />
      </geometry>
      <material
        name="grey_shank"/>
    </visual>
    <collision>
      <origin
        xyz="0 0 0"
        rpy="0 0 0" />
      <geometry>
        <mesh
          filename="../meshes_a1/LH_SHANK.dae" />
      </geometry>
    </collision>
  </link>
  <joint
    name="RL_calf_joint"
    type="revolute">
    <origin
      xyz="0 0 -0.1915"
      rpy="0 0 0" />
    <parent
      link="RL_thigh" />
    <child
      link="RL_calf" />
    <axis
      xyz="0 1 0" />
    <limit effort="55" lower="-4.69653369433" upper="4.916297857297" velocity="10.6"/>

  </joint>

  <link name="FR_foot">
    <inertial>
        <origin xyz="0.0014979844072685 1.99840144432528E-15 7.77349055681165E-05"
        rpy="0 0 0" /> 
      <mass value="0.06"/>
      <inertia ixx="9.6e-06" ixy="0.0" ixz="0.0" iyy="9.6e-06" iyz="0.0" izz="9.6e-06"/>
    </inertial>
      <visual>
        <origin xyz="0 0 0" rpy="0 0 0" />
        <geometry>
          <sphere radius="0.022" />
        </geometry>
              <material
        name="grey_shank"/>
      </visual>
      <collision>
        <origin xyz="0 0 0" rpy="0 0 0" />
        <geometry>
          <sphere radius="0.03" />
        </geometry>
      </collision>
  </link>
  <link name="FL_foot">
    <inertial>
        <origin xyz="0.0014979844072685 1.99840144432528E-15 7.77349055681165E-05"
        rpy="0 0 0" /> 
      <mass value="0.06"/>
      <inertia ixx="9.6e-06" ixy="0.0" ixz="0.0" iyy="9.6e-06" iyz="0.0" izz="9.6e-06"/>
    </inertial>
      <visual>
        <origin xyz="0 0 0" rpy="0 0 0" />
        <geometry>
          <sphere radius="0.022" />
        </geometry>
              <material
        name="grey_shank"/>
      </visual>
      <collision>
        <origin xyz="0 0 0" rpy="0 0 0" />
        <geometry>
          <sphere radius="0.03" />
        </geometry>
      </collision>
  </link>
  <link name="RL_foot">
    <inertial>
        <origin xyz="0.0014979844072685 1.99840144432528E-15 7.77349055681165E-05"
        rpy="0 0 0" /> 
      <mass value="0.06"/>
      <inertia ixx="9.6e-06" ixy="0.0" ixz="0.0" iyy="9.6e-06" iyz="0.0" izz="9.6e-06"/>
    </inertial>
      <visual>
        <origin xyz="0 0 0" rpy="0 0 0" />
        <geometry>
          <sphere radius="0.022" />
        </geometry>
              <material
        name="grey_shank"/>
      </visual>
      <collision>
        <origin xyz="0 0 0" rpy="0 0 0" />
        <geometry>
          <sphere radius="0.03" />
        </geometry>
      </collision>
  </link>
  <link name="RR_foot">
    <inertial>
        <origin xyz="0.0014979844072685 1.99840144432528E-15 7.77349055681165E-05"
        rpy="0 0 0" /> 
      <mass value="0.06"/>
      <inertia ixx="9.6e-06" ixy="0.0" ixz="0.0" iyy="9.6e-06" iyz="0.0" izz="9.6e-06"/>
    </inertial>
      <visual>
        <origin xyz="0 0 0" rpy="0 0 0" />
        <geometry>
          <sphere radius="0.022" />
        </geometry>
        <material
        name="grey_shank"/>
      </visual>
      <collision>
        <origin xyz="0 0 0" rpy="0 0 0" />
        <geometry>
          <sphere radius="0.03" />
        </geometry>
      </collision>
  </link>
  <joint name="RL_foot_fixed" type="fixed" dont_collapse="true" >
    <origin
      xyz="-0.0 0 -0.16802"
      rpy="0 0 0" />
    <parent
      link="RL_calf" />
    <child
      link="RL_foot" />
  </joint>
</robot>
