<?xml version="1.0" ?>
<!-- =================================================================================== -->
<!-- |    This document was autogenerated by xacro from xacro/robot.xacro              | -->
<!-- |    EDITING THIS FILE BY HAND IS NOT RECOMMENDED                                 | -->
<!-- =================================================================================== -->
<robot name="svanm2_description">
  <!-- base -->
  <!-- <xacro:property name="base_com_x" value="0.002585"/>
<xacro:property name="base_com_y" value="0.003221"/>
<xacro:property name="base_com_z" value="0.008796"/>
<xacro:property name="base_mass" value="5.428590"/>
<xacro:property name="base_ixx" value="0.028959"/>
<xacro:property name="base_ixy" value="-0.000021"/>
<xacro:property name="base_ixz" value="0.001591"/>
<xacro:property name="base_iyy" value="0.0601762"/>
<xacro:property name="base_iyz" value="0.000025"/>
<xacro:property name="base_izz" value="0.068516"/> -->
  <!-- without camera mount
<xacro:property name="base_com_x" value="-0.002656"/>
<xacro:property name="base_com_y" value="0.003430"/>
<xacro:property name="base_com_z" value="0.000860"/>
<xacro:property name="base_mass" value="5.016234"/>
<xacro:property name="base_ixx" value="0.023890"/>
<xacro:property name="base_ixy" value="-0.000506"/>
<xacro:property name="base_ixz" value="-0.001154"/>
<xacro:property name="base_iyy" value="0.053100"/>
<xacro:property name="base_iyz" value="-0.000013"/>
<xacro:property name="base_izz" value="0.065972"/> -->
  <!-- <xacro:include filename="$(find m2_description)/xacro/transmission.xacro"/> -->
  <material name="svan_black">
    <color rgba="0.0 0.0 0.0 1.0"/>
  </material>
  <material name="svan_blue">
    <color rgba="0.0 0.0 0.8 1.0"/>
  </material>
  <material name="svan_green">
    <color rgba="0.024 0.251 0.169 1.0"/>
  </material>
  <material name="svan_grey">
    <color rgba="0.5 0.5 0.5 1.0"/>
  </material>

  <mujoco>
    <compiler 
    meshdir="../meshes/"
    discardvisual="false"
    balanceinertia="true"
  />
  </mujoco>
  
  <link name="base">
    <visual>
      <origin rpy="0 0 0" xyz="0 0 0"/>
      <geometry>
        <mesh filename="../meshes/torso.STL" scale="1 1 1"/>
      </geometry>
      <material name="svan_green"/>
    </visual>
    <collision>
      <origin rpy="0 0 0" xyz="0 0 0"/>
      <geometry>
        <box size="0.3762 0.0935 0.154"/>
      </geometry>
    </collision>
    <inertial>
      <origin rpy="0 0 0" xyz="-0.001687 0.00343 0.001498"/>
      <mass value="5.058927"/>
      <inertia ixx="0.024163" ixy="-6e-06" ixz="-0.000785" iyy="0.053914" iyz="-1.3e-05" izz="0.066559"/>
    </inertial>
  </link>
  <!-- hip_link-->
  <link name="FR_hip">
    <inertial>
      <origin rpy="0 0 0" xyz="0.04956 -0.077661 0.001416"/>
      <mass value="1.12767"/>
      <inertia ixx="0.00264" ixy="0.000123" ixz="-1.6e-05" iyy="0.000942" iyz="2e-06" izz="0.00265"/>
    </inertial>
    <visual>
      <origin rpy="0 0 0" xyz="0 0 0"/>
      <geometry>
        <mesh filename="../meshes/FR_hip.STL"/>
      </geometry>
      <material name="svan_grey"/>
    </visual>
    <!-- <collision>
      <origin rpy="0 0 0" xyz="0 0 0"/>
      <geometry>
        <mesh filename="../meshes/FR_hip.STL"/>
      </geometry>
    </collision> -->
  </link>
  <!-- hip_joint -->
  <joint name="FR_hip_joint" type="revolute">
    <origin rpy="0 0 0" xyz="0.155 -0.06 0.0"/>
    <parent link="base"/>
    <child link="FR_hip"/>
    <axis xyz="1 0 0"/>
    <limit effort="12" lower="-4.8" upper="4.8" velocity="20.4"/>
  </joint>
  <!-- thigh link -->
  <link name="FR_thigh">
    <inertial>
      <origin rpy="0 0 0" xyz="-4e-06 -0.000804 -0.060505"/>
      <mass value="0.168956"/>
      <inertia ixx="0.000773" ixy="0" ixz="0" iyy="0.000783" iyz="1.6e-05" izz="4.9e-05"/>
    </inertial>
    <visual>
      <origin rpy="0 0 0" xyz="0 0 0"/>
      <geometry>
        <mesh filename="../meshes/FR_thigh.STL"/>
      </geometry>
      <material name="svan_black"/>
    </visual>
    <collision>
      <origin rpy="0 1.5707963267948966 0" xyz="0 0 -0.1065"/>
      <geometry>
        <box size="0.1715 0.0245 0.034"/>
      </geometry>
    </collision>
  </link>
  <!-- thigh_joint -->
  <joint name="FR_thigh_joint" type="revolute">
    <origin rpy="0 0 0" xyz="0.043751 -0.0796 0"/>
    <parent link="FR_hip"/>
    <child link="FR_thigh"/>
    <axis xyz="0 1 0"/>
    <limit effort="12" lower="-4.047197551" upper="4.188790205" velocity="20.6"/>
  </joint>
  <!-- shank_link-->
  <link name="FR_calf">
    <inertial>
      <origin rpy="0 0 0" xyz="-0.002455 0.00011 -0.065331"/>
      <mass value="0.138935"/>
      <inertia ixx="0.000695" ixy="0" ixz="-3.4e-05" iyy="0.00071" iyz="2e-06" izz="2.6e-05"/>
    </inertial>
    <visual>
      <origin rpy="0 0 0" xyz="0 0 0"/>
      <geometry>
        <mesh filename="../meshes/FR_shank.STL"/>
      </geometry>
      <material name="svan_black"/>
    </visual>
    <collision>
      <origin rpy="0 -0.05 0" xyz="-0.00 0 -0.08"/>
      <geometry>
        <cylinder length="0.09" radius="0.014"/>
      </geometry>
    </collision>
  </link>
  <!-- calf_joint -->
  <joint name="FR_calf_joint" type="revolute">
    <origin rpy="0 0 0" xyz="0 0 -0.1915"/>
    <parent link="FR_thigh"/>
    <child link="FR_calf"/>
    <axis xyz="0 1 0"/>
    <limit effort="20" lower="-4.696533694" upper="4.916297857" velocity="10.6"/>
  </joint>
  <link name="FR_calflower">
    <collision>
      <origin rpy="0 0 0" xyz="0 0 0"/>
      <geometry>
        <cylinder length="0.025" radius="0.015"/>
      </geometry>
    </collision>
  </link>
  <joint name="FR_calflower_joint" type="fixed">
    <origin rpy="0 0.05 0" xyz="0.00 0 -0.137"/>
    <parent link="FR_calf"/>
    <child link="FR_calflower"/>
    <axis xyz="0 0 0"/>
  </joint>
  <link name="FR_calflower1">
    <collision>
      <origin rpy="0 0 0" xyz="0 0 0"/>
      <geometry>
        <cylinder length="0.03" radius="0.0155"/>
      </geometry>
    </collision>
  </link>
  <joint name="FR_calflower1_joint" type="fixed">
    <origin rpy="0 0.4 0" xyz="-0.005 0 -0.02"/>
    <parent link="FR_calflower"/>
    <child link="FR_calflower1"/>
    <axis xyz="0 0 0"/>
  </joint>
  <!-- foot-->
  <link name="FR_foot">
    <contact>
      <friction_anchor/>
      <stiffness value="30000"/>
      <damping value="750"/>
      <spinning_friction value="0.3"/>
      <lateral_friction value="50"/>
    </contact>
    <inertial>
      <origin rpy="0 0 0" xyz="0.001497984407 2e-15 7.77e-05"/>
      <mass value="0.025"/>
      <inertia ixx="2e-06" ixy="0" ixz="0" iyy="2e-06" iyz="0" izz="2e-06"/>
    </inertial>
    <visual>
      <origin rpy="0 0 0" xyz="0 0 0"/>
      <geometry>
        <sphere radius="0.02"/>
      </geometry>
      <material name="svan_grey"/>
    </visual>
    <collision>
      <origin rpy="0 0 0" xyz="0 0 0"/>
      <geometry>
        <sphere radius="0.02"/>
      </geometry>
    </collision>
  </link>
  <!-- <link name="FR_foot_site"/>
  <joint name="FR_foot_site_joint" type="fixed">
    <origin rpy="0 0 0" xyz="0 0 -0.02"/>
    <parent link="FR_foot"/>
    <child link="FR_foot_site"/>
    <axis xyz="0 0 1"/>
    <limit effort="1000" lower="0" upper="0" velocity="0"/>
  </joint> -->
  <!-- foot_joint -->
  <joint name="FR_foot_joint" type="fixed" dont_collapse="true">
    <origin rpy="0 0 0" xyz="-0.01716 0 -0.1685"/>
    <parent link="FR_calf"/>
    <child link="FR_foot"/>
    <axis xyz="0 0 1"/>
  </joint>
  <!-- hip_link-->
  <link name="FL_hip">
    <inertial>
      <origin rpy="0 0 0" xyz="0.04956 0.077661 0.001416"/>
      <mass value="1.12767"/>
      <inertia ixx="0.00264" ixy="-0.000123" ixz="-1.6e-05" iyy="0.000942" iyz="-2e-06" izz="0.00265"/>
    </inertial>
    <visual>
      <origin rpy="0 0 0" xyz="0 0 0"/>
      <geometry>
        <mesh filename="../meshes/FL_hip.STL"/>
      </geometry>
      <material name="svan_grey"/>
    </visual>
    <!-- <collision>
      <origin rpy="0 0 0" xyz="0 0 0"/>
      <geometry>
        <mesh filename="../meshes/FL_hip.STL"/>
      </geometry>
    </collision> -->
  </link>
  <!-- hip_joint -->
  <joint name="FL_hip_joint" type="revolute">
    <origin rpy="0 0 0" xyz="0.155 0.06 0.0"/>
    <parent link="base"/>
    <child link="FL_hip"/>
    <axis xyz="1 0 0"/>
    <limit effort="12" lower="-4.8" upper="4.8" velocity="20.4"/>
  </joint>
  <!-- thigh link -->
  <link name="FL_thigh">
    <inertial>
      <origin rpy="0 0 0" xyz="-4e-06 0.000804 -0.060505"/>
      <mass value="0.168956"/>
      <inertia ixx="0.000773" ixy="0" ixz="0" iyy="0.000783" iyz="-1.6e-05" izz="4.9e-05"/>
    </inertial>
    <visual>
      <origin rpy="0 0 0" xyz="0 0 0"/>
      <geometry>
        <mesh filename="../meshes/FL_thigh.STL"/>
      </geometry>
      <material name="svan_black"/>
    </visual>
    <collision>
      <origin rpy="0 1.5707963267948966 0" xyz="0 0 -0.1065"/>
      <geometry>
        <box size="0.1715 0.0245 0.034"/>
      </geometry>
    </collision>
  </link>
  <!-- thigh_joint -->
  <joint name="FL_thigh_joint" type="revolute">
    <origin rpy="0 0 0" xyz="0.043751 0.0796 0"/>
    <parent link="FL_hip"/>
    <child link="FL_thigh"/>
    <axis xyz="0 1 0"/>
    <limit effort="12" lower="-4.047197551" upper="4.188790205" velocity="20.6"/>
  </joint>
  <!-- shank_link-->
  <link name="FL_calf">
    <inertial>
      <origin rpy="0 0 0" xyz="-0.002455 -0.00011 -0.065331"/>
      <mass value="0.138935"/>
      <inertia ixx="0.000695" ixy="0" ixz="-3.4e-05" iyy="0.00071" iyz="-2e-06" izz="2.6e-05"/>
    </inertial>
    <visual>
      <origin rpy="0 0 0" xyz="0 0 0"/>
      <geometry>
        <mesh filename="../meshes/FL_shank.STL"/>
      </geometry>
      <material name="svan_black"/>
    </visual>
    <collision>
      <origin rpy="0 -0.05 0" xyz="-0.00 0 -0.08"/>
      <geometry>
        <cylinder length="0.09" radius="0.014"/>
      </geometry>
    </collision>
  </link>
  <!-- calf_joint -->
  <joint name="FL_calf_joint" type="revolute">
    <origin rpy="0 0 0" xyz="0 0 -0.1915"/>
    <parent link="FL_thigh"/>
    <child link="FL_calf"/>
    <axis xyz="0 1 0"/>
    <limit effort="20" lower="-4.696533694" upper="4.916297857" velocity="10.6"/>
  </joint>
  <link name="FL_calflower">
    <collision>
      <origin rpy="0 0 0" xyz="0 0 0"/>
      <geometry>
        <cylinder length="0.025" radius="0.015"/>
      </geometry>
    </collision>
  </link>
  <joint name="FL_calflower_joint" type="fixed">
    <origin rpy="0 0.05 0" xyz="0.00 0 -0.137"/>
    <parent link="FL_calf"/>
    <child link="FL_calflower"/>
    <axis xyz="0 0 0"/>
  </joint>
  <link name="FL_calflower1">
    <collision>
      <origin rpy="0 0 0" xyz="0 0 0"/>
      <geometry>
        <cylinder length="0.03" radius="0.0155"/>
      </geometry>
    </collision>
  </link>
  <joint name="FL_calflower1_joint" type="fixed">
    <origin rpy="0 0.4 0" xyz="-0.005 0 -0.02"/>
    <parent link="FL_calflower"/>
    <child link="FL_calflower1"/>
    <axis xyz="0 0 0"/>
  </joint>
  <!-- foot-->
  <link name="FL_foot">
    <contact>
      <friction_anchor/>
      <stiffness value="30000"/>
      <damping value="750"/>
      <spinning_friction value="0.3"/>
      <lateral_friction value="50"/>
    </contact>
    <inertial>
      <origin rpy="0 0 0" xyz="0.001497984407 -2e-15 7.77e-05"/>
      <mass value="0.025"/>
      <inertia ixx="2e-06" ixy="0" ixz="0" iyy="2e-06" iyz="0" izz="2e-06"/>
    </inertial>
    <visual>
      <origin rpy="0 0 0" xyz="0 0 0"/>
      <geometry>
        <sphere radius="0.02"/>
      </geometry>
      <material name="svan_grey"/>
    </visual>
    <collision>
      <origin rpy="0 0 0" xyz="0 0 0"/>
      <geometry>
        <sphere radius="0.02"/>
      </geometry>
    </collision>
  </link>
  <!-- <link name="FL_foot_site"/>
  <joint name="FL_foot_site_joint" type="fixed">
    <origin rpy="0 0 0" xyz="0 0 -0.02"/>
    <parent link="FL_foot"/>
    <child link="FL_foot_site"/>
    <axis xyz="0 0 1"/>
    <limit effort="1000" lower="0" upper="0" velocity="0"/>
  </joint> -->
  <!-- foot_joint -->
  <joint name="FL_foot_joint" type="fixed" dont_collapse="true">
    <origin rpy="0 0 0" xyz="-0.01716 0 -0.1685"/>
    <parent link="FL_calf"/>
    <child link="FL_foot"/>
    <axis xyz="0 0 1"/>
  </joint>
  <!-- hip_link-->
  <link name="RR_hip">
    <inertial>
      <origin rpy="0 0 0" xyz="-0.04956 -0.077661 0.001416"/>
      <mass value="1.12767"/>
      <inertia ixx="0.00264" ixy="-0.000123" ixz="1.6e-05" iyy="0.000942" iyz="2e-06" izz="0.00265"/>
    </inertial>
    <visual>
      <origin rpy="3.14159265359 3.14159265359 0" xyz="0 0 0"/>
      <geometry>
        <mesh filename="../meshes/FL_hip.STL"/>
      </geometry>
      <material name="svan_grey"/>
    </visual>
    <!-- <collision>
      <origin rpy="3.14159265359 3.14159265359 0" xyz="0 0 0"/>
      <geometry>
        <mesh filename="../meshes/FL_hip.STL"/>
      </geometry>
    </collision> -->
  </link>
  <!-- hip_joint -->
  <joint name="RR_hip_joint" type="revolute">
    <origin rpy="0 0 0" xyz="-0.155 -0.06 0.0"/>
    <parent link="base"/>
    <child link="RR_hip"/>
    <axis xyz="1 0 0"/>
    <limit effort="12" lower="-4.8" upper="4.8" velocity="20.4"/>
  </joint>
  <!-- thigh link -->
  <link name="RR_thigh">
    <inertial>
      <origin rpy="0 0 0" xyz="4e-06 -0.000804 -0.060505"/>
      <mass value="0.168956"/>
      <inertia ixx="0.000773" ixy="0" ixz="0" iyy="0.000783" iyz="1.6e-05" izz="4.9e-05"/>
    </inertial>
    <visual>
      <origin rpy="0 0 0" xyz="0 0 0"/>
      <geometry>
        <mesh filename="../meshes/FR_thigh.STL"/>
      </geometry>
      <material name="svan_black"/>
    </visual>
    <collision>
      <origin rpy="0 1.5707963267948966 0" xyz="0 0 -0.1065"/>
      <geometry>
        <box size="0.1715 0.0245 0.034"/>
      </geometry>
    </collision>
  </link>
  <!-- thigh_joint -->
  <joint name="RR_thigh_joint" type="revolute">
    <origin rpy="0 0 0" xyz="-0.043751 -0.0796 0"/>
    <parent link="RR_hip"/>
    <child link="RR_thigh"/>
    <axis xyz="0 1 0"/>
    <limit effort="12" lower="-4.047197551" upper="4.188790205" velocity="20.6"/>
  </joint>
  <!-- shank_link-->
  <link name="RR_calf">
    <inertial>
      <origin rpy="0 0 0" xyz="0.002455 0.00011 -0.065331"/>
      <mass value="0.138935"/>
      <inertia ixx="0.000695" ixy="0" ixz="-3.4e-05" iyy="0.00071" iyz="2e-06" izz="2.6e-05"/>
    </inertial>
    <visual>
      <origin rpy="0 0 0" xyz="0 0 0"/>
      <geometry>
        <mesh filename="../meshes/FR_shank.STL"/>
      </geometry>
      <material name="svan_black"/>
    </visual>
    <collision>
      <origin rpy="0 -0.05 0" xyz="-0.00 0 -0.08"/>
      <geometry>
        <cylinder length="0.09" radius="0.014"/>
      </geometry>
    </collision>
  </link>
  <!-- calf_joint -->
  <joint name="RR_calf_joint" type="revolute">
    <origin rpy="0 0 0" xyz="0 0 -0.1915"/>
    <parent link="RR_thigh"/>
    <child link="RR_calf"/>
    <axis xyz="0 1 0"/>
    <limit effort="20" lower="-4.696533694" upper="4.916297857" velocity="10.6"/>
  </joint>
  <link name="RR_calflower">
    <collision>
      <origin rpy="0 0 0" xyz="0 0 0"/>
      <geometry>
        <cylinder length="0.025" radius="0.015"/>
      </geometry>
    </collision>
  </link>
  <joint name="RR_calflower_joint" type="fixed">
    <origin rpy="0 0.05 0" xyz="0.00 0 -0.137"/>
    <parent link="RR_calf"/>
    <child link="RR_calflower"/>
    <axis xyz="0 0 0"/>
  </joint>
  <link name="RR_calflower1">
    <collision>
      <origin rpy="0 0 0" xyz="0 0 0"/>
      <geometry>
        <cylinder length="0.03" radius="0.0155"/>
      </geometry>
    </collision>
  </link>
  <joint name="RR_calflower1_joint" type="fixed">
    <origin rpy="0 0.4 0" xyz="-0.005 0 -0.02"/>
    <parent link="RR_calflower"/>
    <child link="RR_calflower1"/>
    <axis xyz="0 0 0"/>
  </joint>
  <!-- foot-->
  <link name="RR_foot">
    <contact>
      <friction_anchor/>
      <stiffness value="30000"/>
      <damping value="750"/>
      <spinning_friction value="0.3"/>
      <lateral_friction value="50"/>
    </contact>
    <inertial>
      <origin rpy="0 0 0" xyz="-0.001497984407 2e-15 7.77e-05"/>
      <mass value="0.025"/>
      <inertia ixx="2e-06" ixy="0" ixz="0" iyy="2e-06" iyz="0" izz="2e-06"/>
    </inertial>
    <visual>
      <origin rpy="0 0 0" xyz="0 0 0"/>
      <geometry>
        <sphere radius="0.02"/>
      </geometry>
      <material name="svan_grey"/>
    </visual>
    <collision>
      <origin rpy="0 0 0" xyz="0 0 0"/>
      <geometry>
        <sphere radius="0.02"/>
      </geometry>
    </collision>
  </link>
  <!-- <link name="RR_foot_site"/>
  <joint name="RR_foot_site_joint" type="fixed">
    <origin rpy="0 0 0" xyz="0 0 -0.02"/>
    <parent link="RR_foot"/>
    <child link="RR_foot_site"/>
    <axis xyz="0 0 1"/>
    <limit effort="1000" lower="0" upper="0" velocity="0"/>
  </joint> -->
  <!-- I think it is a good idea to keep a separate joint to mark the foot end location. -->
  <!-- Changing the z-position -0.1685 -> -0.1885 by hand for now -->
  <!-- Update: Lol this is not even being used anywhere in kinodynamics -->
  <!-- foot_joint -->
  <joint name="RR_foot_joint" type="fixed" dont_collapse="true">
    <origin rpy="0 0 0" xyz="-0.01716 0 -0.1685"/>
    <parent link="RR_calf"/>
    <child link="RR_foot"/>
    <axis xyz="0 0 1"/>
  </joint>
  <!-- hip_link-->
  <link name="RL_hip">
    <inertial>
      <origin rpy="0 0 0" xyz="-0.04956 0.077661 0.001416"/>
      <mass value="1.12767"/>
      <inertia ixx="0.00264" ixy="0.000123" ixz="1.6e-05" iyy="0.000942" iyz="-2e-06" izz="0.00265"/>
    </inertial>
    <visual>
      <origin rpy="3.14159265359 3.14159265359 0" xyz="0 0 0"/>
      <geometry>
        <mesh filename="../meshes/FR_hip.STL"/>
      </geometry>
      <material name="svan_grey"/>
    </visual>
    <!-- <collision>
      <origin rpy="3.14159265359 3.14159265359 0" xyz="0 0 0"/>
      <geometry>
        <mesh filename="../meshes/FR_hip.STL"/>
      </geometry>
    </collision> -->
  </link>
  <!-- hip_joint -->
  <joint name="RL_hip_joint" type="revolute">
    <origin rpy="0 0 0" xyz="-0.155 0.06 0.0"/>
    <parent link="base"/>
    <child link="RL_hip"/>
    <axis xyz="1 0 0"/>
    <limit effort="12" lower="-4.8" upper="4.8" velocity="20.4"/>
  </joint>
  <!-- thigh link -->
  <link name="RL_thigh">
    <inertial>
      <origin rpy="0 0 0" xyz="4e-06 0.000804 -0.060505"/>
      <mass value="0.168956"/>
      <inertia ixx="0.000773" ixy="0" ixz="0" iyy="0.000783" iyz="-1.6e-05" izz="4.9e-05"/>
    </inertial>
    <visual>
      <origin rpy="0 0 0" xyz="0 0 0"/>
      <geometry>
        <mesh filename="../meshes/FL_thigh.STL"/>
      </geometry>
      <material name="svan_black"/>
    </visual>
    <collision>
      <origin rpy="0 1.5707963267948966 0" xyz="0 0 -0.1065"/>
      <geometry>
        <box size="0.1715 0.0245 0.034"/>
      </geometry>
    </collision>
  </link>
  <!-- thigh_joint -->
  <joint name="RL_thigh_joint" type="revolute">
    <origin rpy="0 0 0" xyz="-0.043751 0.0796 0"/>
    <parent link="RL_hip"/>
    <child link="RL_thigh"/>
    <axis xyz="0 1 0"/>
    <limit effort="12" lower="-4.047197551" upper="4.188790205" velocity="20.6"/>
  </joint>
  <!-- shank_link-->
  <link name="RL_calf">
    <inertial>
      <origin rpy="0 0 0" xyz="0.002455 -0.00011 -0.065331"/>
      <mass value="0.138935"/>
      <inertia ixx="0.000695" ixy="0" ixz="-3.4e-05" iyy="0.00071" iyz="-2e-06" izz="2.6e-05"/>
    </inertial>
    <visual>
      <origin rpy="0 0 0" xyz="0 0 0"/>
      <geometry>
        <mesh filename="../meshes/FL_shank.STL"/>
      </geometry>
      <material name="svan_black"/>
    </visual>
    <collision>
      <origin rpy="0 -0.05 0" xyz="-0.00 0 -0.08"/>
      <geometry>
        <cylinder length="0.09" radius="0.014"/>
      </geometry>
    </collision>
  </link>
  <!-- calf_joint -->
  <joint name="RL_calf_joint" type="revolute">
    <origin rpy="0 0 0" xyz="0 0 -0.1915"/>
    <parent link="RL_thigh"/>
    <child link="RL_calf"/>
    <axis xyz="0 1 0"/>
    <limit effort="20" lower="-4.696533694" upper="4.916297857" velocity="10.6"/>
  </joint>
  <link name="RL_calflower">
    <collision>
      <origin rpy="0 0 0" xyz="0 0 0"/>
      <geometry>
        <cylinder length="0.025" radius="0.015"/>
      </geometry>
    </collision>
  </link>
  <joint name="RL_calflower_joint" type="fixed">
    <origin rpy="0 0.05 0" xyz="0.00 0 -0.137"/>
    <parent link="RL_calf"/>
    <child link="RL_calflower"/>
    <axis xyz="0 0 0"/>
  </joint>
  <link name="RL_calflower1">
    <collision>
      <origin rpy="0 0 0" xyz="0 0 0"/>
      <geometry>
        <cylinder length="0.03" radius="0.0155"/>
      </geometry>
    </collision>
  </link>
  <joint name="RL_calflower1_joint" type="fixed">
    <origin rpy="0 0.4 0" xyz="-0.005 0 -0.02"/>
    <parent link="RL_calflower"/>
    <child link="RL_calflower1"/>
    <axis xyz="0 0 0"/>
  </joint>
  <!-- foot-->
  <link name="RL_foot">
    <contact>
      <friction_anchor/>
      <stiffness value="30000"/>
      <damping value="750"/>
      <spinning_friction value="0.3"/>
      <lateral_friction value="50"/>
    </contact>
    <inertial>
      <origin rpy="0 0 0" xyz="-0.001497984407 -2e-15 7.77e-05"/>
      <mass value="0.025"/>
      <inertia ixx="2e-06" ixy="0" ixz="0" iyy="2e-06" iyz="0" izz="2e-06"/>
    </inertial>
    <visual>
      <origin rpy="0 0 0" xyz="0 0 0"/>
      <geometry>
        <sphere radius="0.02"/>
      </geometry>
      <material name="svan_grey"/>
    </visual>
    <collision>
      <origin rpy="0 0 0" xyz="0 0 0"/>
      <geometry>
        <sphere radius="0.02"/>
      </geometry>
    </collision>
  </link>
  <!-- foot_joint -->
  <joint name="RL_foot_joint" type="fixed" dont_collapse="true">
    <origin rpy="0 0 0" xyz="-0.01716 0 -0.1685"/>
    <parent link="RL_calf"/>
    <child link="RL_foot"/>
    <axis xyz="0 0 1"/>
  </joint>
</robot>
